# IPython log file

>>> from testapp.models import *
>>> Connections.objects.all()
Traceback (most recent call last):
     ...
OperationalError: no such column: connections.id

